Workbook

Sheet Tills
A1: Bar 1 - Vol 1 | G1: Bar 2 - Vol 2 | M1: Bar 3 - Pimm's Stretch | R1: Bar 4 - Cocktail / Aperol | X1: Bar 5 - Spitfire Bar | AC1: Bar 6 - Can Bar | AF1: Bar 7 - VIP | AL1: Bar 8 - Vol 3 | AR1: Bar 9 - Red Bull | AV1: Bar 10 - Zu Bar | AZ1: Bar 11 - Wine Van
A2: Category | B2: Product | D2: Pint | E2: Half | G2: Category | H2: Product | J2: Pint | K2: Half | M2: Category | N2: Product | R2: Category | S2: Product | T2: 25ml | U2: 50ml | V2: 175ml | W2: 200ml | X2: Category | Y2: Product | AC2: Category | AD2: Product | AE2: Can | AF2: Category | AG2: Product | AI2: Pint | AJ2: Half | AL2: Category | AM2: Product | AO2: Pint | AP2: Half | AR2: Category | AS2: Product | AT2: 25ml | AU2: 50ml | AW2: Product | AX2: 25ml | AY2: 50ml | AZ2: Category | BA2: Product | BB2: ABV% | BC2: Bottle | BD2: Can
A3: Draught | B3: Spitfire Lager | D3: 7 | E3: 3.5 | G3: Draught | H3: Spitfire Lager | J3: 7 | K3: 3.5 | M3: Packaged | N3: Glass of Pimm's | O3: 10 | R3: Spirit | S3: Aperol Spirtz | U3: 12 | X3: Draught | Y3: Spitfire Lager | Z3: 7 | AA3: 3.5 | AE3: 330ml | AF3: Draught | AG3: Spitfire Lager | AI3: 7 | AJ3: 3.5 | AL3: Draught | AM3: Spitfire Lager | AO3: 7 | AP3: 3.5 | AR3: Spirit + Mixer | AS3: Vodka & Red Bull | AT3: 10 | AU3: 15 | AV3: Mixed Drinks | AW3: Zubrowka Biala & Cranberry | AX3: 8 | AY3: 13 | AZ3: Wine
B4: Orchard View | D4: 7 | E4: 3.5 | H4: Orchard View | J4: 7 | K4: 3.5 | N4: Jug of Pimm's | O4: 28 | S4: Aperol & Lemonade | U4: 7 | Y4: Orchard View | Z4: 7 | AA4: 3.5 | AD4: Camden Hells | AE4: 6 | AG4: Cruzcampo | AI4: 7.5 | AJ4: 4 | AM4: Orchard View | AO4: 7 | AP4: 3.5 | AS4: Tropical RumBull | AT4: 10 | AU4: 15 | AW4: Zubrowka Bison Grass & Sparkling Apple | AX4: 8 | AY4: 13 | BA4: Monte Carlo Blush | BC4: 33 | BD4: 12
AE5: 440ml | AG5: Orchard View | AI5: 7 | AJ5: 3.5 | AS5: Watermelon Ginbull | AT5: 10 | AU5: 15 | AW5: Zubrowka Vanilla & Coke | AX5: 8 | AY5: 13
D6: 25ml | E6: 50ml | J6: 25ml | K6: 50ml | N6: Jug Deposit (+refund needed) | O6: 10 | S6: Tom's Cocktails Margarherta | V6: 11 | Y6: Water | Z6: 3 | AD6: Stowford Press Apple Cider | AE6: 6.5 | AO6: 25ml | AP6: 50ml | AW6: Zubrowka Raspberry Lemonade | AX6: 8 | AY6: 13
A7: Spirit + Mixer | B7: Smirnoff Vodka | D7: 6 | E7: 11 | G7: Spirit + Mixer | H7: Zubrowka Biala | J7: 6 | K7: 11 | S7: Tom's Cocktails Paloma | V7: 11 | Y7: CAN Coca Cola Zero 330ml | Z7: 3 | AD7: Stowford Press Mixed Berry cider | AE7: 6.5 | AI7: 25ml | AJ7: 50ml | AL7: Spirit + Mixer | AM7: Zubrowka Biala | AO7: 6 | AP7: 11 | AS7: Jagerbomb | AT7: 7 | AW7: Zubrowka Mango Passionfruit Spritz | AX7: 8 | AY7: 13
B8: Gordan's Gin | D8: 6 | E8: 11 | H8: Gordan's Gin | J8: 6 | K8: 11 | Y8: CAN Lemonade 330ml Can | Z8: 3 | AE8: 250ml | AF8: Spirit + Mixer | AG8: Zubrowka Biala | AI8: 6 | AJ8: 11 | AM8: Gordan's Gin | AO8: 6 | AP8: 11
B9: Gordan's Pink Gin | D9: 6 | E9: 11 | H9: Gordan's Pink Gin | J9: 6 | K9: 11 | R9: Cocktails (BIB) | AD9: Mason Vodka & Lemonade | AE9: 7 | AG9: Gordan's Gin | AI9: 6 | AJ9: 11 | AM9: Gordan's Pink Gin | AO9: 6 | AP9: 11
B10: Captain Morgan's Spiced | D10: 6 | E10: 11 | H10: Myst Spiced Apple Rum | J10: 6 | K10: 11 | S10: Espresso Martini | W10: 12 | AD10: Portobello Road Gin & Tonic | AE10: 7 | AG10: Gordan's Pink Gin | AI10: 6 | AJ10: 11 | AM10: Myst Spiced Apple Rum | AO10: 6 | AP10: 11 | AS10: Red Bull Energy Drink | AT10: 4 | AV10: Spirit & Mixer | AW10: Zubrowka Bison Grass Vodka | AX10: 6 | AY10: 11
B11: Jack Danial's | D11: 6 | E11: 11 | H11: Jack Danial's | J11: 6 | K11: 11 | S11: PassionFruit Martini | W11: 12 | AD11: Red Leg Spiced Rum & Cola | AE11: 7 | AG11: Myst Spiced Apple Rum | AI11: 6 | AJ11: 11 | AM11: Jack Danial's | AO11: 6 | AP11: 11 | AS11: Red Bull Sugar Free | AT11: 4 | AW11: Zubrowka Vanilla Vodka | AX11: 6 | AY11: 11
D12: 25ml | E12: 50ml | J12: 25ml | K12: 50ml | AE12: 330ml | AG12: Jack Danial's | AI12: 6 | AJ12: 11 | AO12: 25ml | AP12: 50ml | AS12: Red Bull Tropical | AT12: 4 | AW12: Zubrowka Biala Vodka | AX12: 6 | AY12: 11
B13: Vodka Red Bull | D13: 10 | E13: 15 | H13: Vodka Red Bull | J13: 10 | K13: 15 | AD13: Jack Daniel's & Coke | AE13: 7 | AI13: 25ml | AJ13: 50ml | AL13: Mixed Drinks | AM13: Zubrowka Raspberry Lemonade | AP13: 13 | AS13: Red Bull Watermelon | AT13: 4 | AW13: Zubrowka Raspberry Vodka | AX13: 6 | AY13: 11
B14: Tequila Peach Bull | D14: 10 | E14: 15 | H14: Tequila Peach Bull | J14: 10 | K14: 15 | AE14: 250ml | AF14: Mixed Drinks | AG14: Zubrowka Raspberry Lemonade | AJ14: 13 | AM14: Zubrowka Mango Passionfruit Sprits | AP14: 13 | AW14: Zubrowka Mango & Passionfruit Vodka | AX14: 6 | AY14: 11
B15: Citrus Lime Bull | D15: 10 | E15: 15 | H15: Citrus Lime Bull | J15: 10 | K15: 15 | AC15: Wine | AD15: Monte Carlo Blush Cans | AE15: 12 | AG15: Zubrowka Mango Passionfruit Sprits | AJ15: 13 | AM15: Vodka Red Bull | AO15: 10 | AP15: 15 | AS15: Water | AT15: 2.5
D16: 25ml | E16: 3 for | J16: 25ml | K16: 3 for | AG16: Vodka Red Bull | AI16: 10 | AJ16: 15 | AM16: Tropical Rum Bull | AO16: 10 | AP16: 15 | AX16: 25ml | AY16: 3 for
A17: Shots | B17: Jagermeister | D17: 5 | G17: Shots | H17: Myst Caramel Tequila | J17: 5 | K17: 12 | AC17: Softs | AE17: 500ml | AG17: Tropical Rum Bull | AI17: 10 | AJ17: 15 | AM17: Watermelon Ginbull | AO17: 10 | AP17: 15 | AV17: Shots | AW17: Fresh Zu Cherry & Lime | AX17: 5 | AY17: 12
B18: Jagerbomb | D18: 7 | H18: Myst Coffee Tequila | J18: 5 | K18: 12 | AD18: Water | AE18: 2.5 | AG18: Watermelon Ginbull | AI18: 10 | AJ18: 15 | AO18: 25ml | AP18: 3 for | AW18: Fresh Zu Apple | AX18: 5 | AY18: 12
A19: Wine | D19: Bottle | E19: 250ml | F19: 125ml | H19: Jagermeister | J19: 5 | AE19: 330ml | AK19: 175ml | AL19: Shots | AM19: Myst Caramel Tequila | AO19: 5 | AP19: 12
B20: Rose Wine | D20: 33 | E20: 12 | F20: 6 | H20: Jagerbomb | J20: 7 | AD20: CAN Coca Cola Zero 330ml | AE20: 3 | AF20: Cocktails | AG20: Tom's Cocktails Margarherta | AK20: 11 | AM20: Myst Coffee Tequila | AO20: 5 | AP20: 12 | AV20: Softs | AX20: Dash | AY20: Can
B21: White Wine | D21: 33 | E21: 12 | F21: 6 | AD21: CAN Lemonade 330ml Can | AE21: 3 | AG21: Tom's Cocktails Paloma | AK21: 11 | AM21: Jagermeister | AO21: 5 | AW21: Water 500ml | AY21: 2.5
G22: Wine | J22: Bottle | K22: 250ml | L22: 125ml | N22: 140 | O22: Jager | AK22: 200ml | AM22: Jagerbomb | AO22: 7 | AW22: CAN Coca Cola Zero 330ml | AX22: 2 | AY22: 3
B23: Prosecco | D23: 35 | E23: 8.5 | F23: 6.5 | H23: Monte Carlo Blush Rose | J23: 33 | K23: 12 | L23: 6 | N23: 110 | O23: Myst / Roae | AG23: Espresso Martini | AK23: 12 | AW23: CAN Lemonade 330ml Can | AX23: 2 | AY23: 3
B24: Carafe Deposit (+refund needed) | D24: 10 | H24: White Wine | J24: 33 | K24: 12 | L24: 6 | AG24: PassionFruit Martini | AK24: 12 | AL24: Wine | AO24: Bottle | AP24: 250ml | AQ24: 125ml | AW24: Schweppes Tonic 1L PET | AX24: 2
A25: Softs | C25: Dash | D25: Can | E25: Pint | F25: Half | AI25: 25ml | AJ25: 3 for | AM25: Monte Carlo Blush Rose | AO25: 33 | AP25: 12 | AQ25: 6 | AW25: Schweppes Soda 1L | AX25: 2
B26: Water 500ml | D26: 2.5 | H26: Prosecco | J26: 35 | K26: 8.5 | L26: 6.5 | AF26: Shots | AG26: Myst Caramel Tequila | AI26: 5 | AJ26: 12 | AM26: White Wine | AO26: 33 | AP26: 12 | AQ26: 6 | AW26: Orange Juice | AX26: 2
B27: CAN Coca Cola Zero 330ml | C27: 1.6 | D27: 3.2 | H27: Carafe Deposit (+refund needed) | J27: 10 | AG27: Myst Coffee Tequila | AI27: 5 | AJ27: 12 | AW27: Cranberry Juice | AX27: 2
B28: CAN Lemonade 330ml Can | C28: 1.6 | D28: 3.2 | AG28: Jagermeister | AI28: 5.5 | AM28: Prosecco | AO28: 35 | AP28: 8.5 | AQ28: 6.5 | AW28: Red Bull Energy Drink | AY28: 4
B29: Schweppes Tonic 1L PET | C29: 1.6 | E29: 3 | F29: 2 | G29: Softs | I29: Dash | J29: Can | K29: Pint | L29: Half | AG29: Jagerbomb | AI29: 7.5 | AM29: Carafe Deposit (+refund needed) | AO29: 10 | AW29: Red Bull Sugar Free | AY29: 4
B30: Schweppes Soda 1L | C30: 1.6 | E30: 3 | F30: 2 | H30: Water 500ml | J30: 2.5 | AW30: Red Bull Tropical | AY30: 4
B31: Red Bull Energy Drink | D31: 4.5 | H31: CAN Coca Cola Zero 330ml | I31: 2 | J31: 3 | AF31: Wine | AI31: Bottle | AJ31: 250ml | AK31: 125ml | AL31: Softs | AN31: Dash | AO31: Can | AP31: Pint | AQ31: Half | AW31: Red Bull Watermelon | AY31: 4
B32: Red Bull Sugar Free | D32: 4.5 | H32: CAN Lemonade 330ml Can | I32: 2 | J32: 3 | AG32: Monte Carlo Blush Rose | AI32: 33 | AJ32: 12 | AK32: 6 | AM32: Water 500ml | AO32: 2.5
B33: Red Bull Tropical | D33: 4.5 | H33: Schweppes Tonic 1L PET | I33: 2 | K33: 3 | L33: 2 | AG33: White Wine | AI33: 33 | AJ33: 12 | AK33: 6 | AM33: CAN Coca Cola Zero 330ml | AN33: 2 | AO33: 3
B34: Red Bull Watermelon | D34: 4.5 | H34: Schweppes Soda 1L | I34: 2 | K34: 3 | L34: 2 | AM34: CAN Lemonade 330ml Can | AN34: 2 | AO34: 3
H35: Red Bull Energy Drink | J35: 4 | AG35: Prosecco | AI35: 35 | AJ35: 8.5 | AK35: 6.5 | AM35: Schweppes Tonic 1L PET | AN35: 2 | AP35: 3 | AQ35: 2
H36: Red Bull Sugar Free | J36: 4 | AG36: Carafe Deposit (+refund needed) | AI36: 10 | AM36: Schweppes Soda 1L | AN36: 2 | AP36: 3 | AQ36: 2
H37: Red Bull Tropical | J37: 4 | AM37: Red Bull Energy Drink | AO37: 4
H38: Red Bull Watermelon | J38: 4 | AF38: Softs | AH38: Dash | AI38: Can | AJ38: Pint | AK38: Half | AM38: Red Bull Sugar Free | AO38: 4
AG39: Water 500ml | AI39: 2.5 | AM39: Red Bull Tropical | AO39: 4
AG40: CAN Coca Cola Zero 330ml | AH40: 2 | AI40: 3 | AM40: Red Bull Watermelon | AO40: 4
...

Sheet Menu
A1: Bar 1 - Vol 1 | H1: Bar 2 - Vol 2 | O1: Bar 3 - Pimm's Stretch | U1: Bar 4 - Cocktail / Aperol | AB1: Bar 6 - Can Bar | AF1: Bar 7 - VIP | AM1: Bar 8 - Vol 3 | AT1: Bar 9 - Red Bull | AY1: Bar 10 - Hooch Bar | BD1: Bar 11 - Garden Party VIP
A2: Category | B2: Product | C2: ABV | D2: Pint | E2: Half | H2: Category | I2: Product | K2: Pint | L2: Half | O2: Category | P2: Product | U2: Category | V2: Product | W2: ABV% | X2: 25ml | Y2: 50ml | Z2: 175ml | AA2: 200ml | AB2: Category | AC2: Product | AE2: Can | AF2: Category | AG2: Product | AI2: Pint | AJ2: Half | AM2: Category | AN2: Product | AP2: Pint | AQ2: Half | AT2: Category | AU2: Product | AV2: ABV | AW2: Half | AZ2: Product | BA2: ABV% | BB2: 440ml | BD2: Category | BE2: Product | BG2: Pint | BH2: Half
A3: Draught | B3: Spitfire Lager | C3: 0.04 | D3: 7.9 | E3: 4 | H3: Draught | I3: Spitfire Lager | J3: 0.04 | K3: 7.9 | L3: 4 | O3: Packaged | P3: Glass of Pimm's | Q3: 0.054 | R3: 11 | U3: Spirit | V3: Aperol Spirtz | W3: 0.04 | Y3: 12 | AE3: 330ml | AF3: Draught | AG3: Spitfire Lager | AH3: 0.04 | AI3: 7.9 | AJ3: 4 | AM3: Draught | AN3: Spitfire Lager | AO3: 0.04 | AP3: 7.9 | AQ3: 4 | AT3: Spirit + Mixer | AU3: Vodka Red Bull | AV3: 0.375 | AW3: 10.5 | AX3: 15.5 | AY3: Mixed Drinks | AZ3: Hooch Lemon | BA3: 0.04 | BB3: 7 | BD3: Draught | BE3: Spitfire Lager | BF3: 0.04 | BG3: 7.9 | BH3: 4
B4: Orchard View | C4: 0.045 | D4: 7.9 | E4: 4 | I4: Orchard View | J4: 0.045 | K4: 7.9 | L4: 4 | P4: Jug of Pimm's | Q4: 0.054 | R4: 30 | V4: Aperol & Lemonade | W4: 0.11 | Y4: 7 | AC4: TBC | AD4: 0.046 | AE4: 6 | AG4: Orchard View | AH4: 0.045 | AI4: 7.9 | AJ4: 4 | AN4: Orchard View | AO4: 0.045 | AP4: 7.9 | AQ4: 4 | AU4: Tequila Peach Bull | AV4: 0.26 | AW4: 10.5 | AX4: 15.5 | AZ4: Hooch Raspberry | BA4: 0.034 | BB4: 7 | BE4: Orchard View | BF4: 0.045 | BG4: 7.9 | BH4: 4
AE5: 440ml | AU5: Citrus Lime Bull | AV5: 0.375 | AW5: 10.5 | AX5: 15.5 | AZ5: Hooch Tropical | BA5: 0.034 | BB5: 7
D6: 25ml | E6: 50ml | K6: 25ml | L6: 50ml | P6: Jug Deposit (+refund needed) | R6: 10 | U6: Cocktails (BIB) | AC6: Stowford Press Apple Cider | AD6: 0.04 | AE6: 6 | AI6: 25ml | AJ6: 50ml | AP6: 25ml | AQ6: 50ml | AZ6: Hooch Cherry | BA6: 0.043 | BB6: 7 | BG6: 25ml | BH6: 50ml
A7: Spirit + Mixer | B7: Smirnoff Vodka | C7: 0.375 | D7: 8 | E7: 13 | H7: Spirit + Mixer | I7: Smirnoff Vodka | J7: 0.375 | K7: 8 | L7: 13 | V7: Espresso Martini | AA7: 12 | AC7: Stowford Press Mixed Berry cider | AD7: 0.04 | AE7: 6 | AF7: Spirit + Mixer | AG7: Smirnoff Vodka | AH7: 0.375 | AI7: 8 | AJ7: 13 | AM7: Spirit + Mixer | AN7: Smirnoff Vodka | AO7: 0.375 | AP7: 8 | AQ7: 13 | AU7: Jagerbomb | AV7: 0.35 | AW7: 7.5 | AZ7: Hooch Peach | BA7: 0.034 | BB7: 7 | BD7: Spirit + Mixer | BE7: Smirnoff Vodka | BF7: 0.375 | BG7: 8 | BH7: 13
B8: Gordan's Gin | C8: 0.375 | D8: 8 | E8: 13 | I8: Gordan's Gin | J8: 0.375 | K8: 8 | L8: 13 | V8: PassionFruit Martini | AA8: 12 | AE8: 250ml | AG8: Gordan's Gin | AH8: 0.375 | AI8: 8 | AJ8: 13 | AN8: Gordan's Gin | AO8: 0.375 | AP8: 8 | AQ8: 13 | BE8: Gordan's Gin | BF8: 0.375 | BG8: 8 | BH8: 13
B9: Gordan's Pink Gin | C9: 0.375 | D9: 8 | E9: 13 | I9: Gordan's Pink Gin | J9: 0.375 | K9: 8 | L9: 13 | AC9: Mason Vodka & Lemonade | AD9: 0.045 | AE9: 7 | AG9: Gordan's Pink Gin | AH9: 0.375 | AI9: 8 | AJ9: 13 | AN9: Gordan's Pink Gin | AO9: 0.375 | AP9: 8 | AQ9: 13 | AU9: Red Bull Energy Drink | AW9: 4.5 | AY9: Softs | BB9: Can | BE9: Gordan's Pink Gin | BF9: 0.375 | BG9: 8 | BH9: 13
B10: Captain Morgan's Spiced | C10: 0.26 | D10: 8 | E10: 13 | I10: Captain Morgan's Spiced | J10: 0.26 | K10: 8 | L10: 13 | AC10: Portobello Road Gin & Tonic | AD10: 0.05 | AE10: 7 | AG10: Captain Morgan's Spiced | AH10: 0.26 | AI10: 8 | AJ10: 13 | AN10: Captain Morgan's Spiced | AO10: 0.26 | AP10: 8 | AQ10: 13 | AU10: Red Bull Sugarfree | AW10: 4.5 | AZ10: Water 500ml | BB10: 2.5 | BE10: Captain Morgan's Spiced | BF10: 0.26 | BG10: 8 | BH10: 13
B11: Jack Danial's | C11: 0.4 | D11: 8 | E11: 13 | I11: Jack Danial's | J11: 0.4 | K11: 8 | L11: 13 | AC11: Red Leg Spiced Rum & Cola | AD11: 0.05 | AE11: 7 | AG11: Jack Danial's | AH11: 0.4 | AI11: 8 | AJ11: 13 | AN11: Jack Danial's | AO11: 0.4 | AP11: 8 | AQ11: 13 | AU11: Red Bull Peach Edition | AW11: 4.5 | BE11: Jack Danial's | BF11: 0.4 | BG11: 8 | BH11: 13
A12: Mixer's - Coke Zero, Lemonade, Tonic, Juice | H12: Mixer's - Coke Zero, Lemonade, Tonic, Juice | AE12: 330ml | AF12: Mixer's - Coke Zero, Lemonade, Tonic, Juice | AM12: Mixer's - Coke Zero, Lemonade, Tonic, Juice | AU12: Red Bull Citrus Zest Edition | AW12: 4.5 | BD12: Mixer's - Coke Zero, Lemonade, Tonic, Juice
A13: Premium Mixer - Red Bull, Sugar Free, White Peach, Citrus Zest + £2.50 | H13: Premium Mixer - Red Bull, Sugar Free, White Peach, Citrus Zest + £2.50 | AC13: Jack Daniel's & Coke | AD13: 0.05 | AE13: 7 | AF13: Premium Mixer - Red Bull, Sugar Free, White Peach, Citrus Zest + £2.50 | AM13: Premium Mixer - Red Bull, Sugar Free, White Peach, Citrus Zest + £2.50 | BD13: Premium Mixer - Red Bull, Sugar Free, White Peach, Citrus Zest + £2.50
D14: 125ml | E14: 200ml | F14: 440ml | K14: 125ml | L14: 200ml | M14: 440ml | AE14: 250ml | AI14: 125ml | AJ14: 200ml | AK14: 440ml | AP14: 125ml | AQ14: 200ml | AR14: 440ml | AU14: Water | AW14: 2.5 | BG14: 125ml | BH14: 200ml | BI14: 440ml
A15: Ready To Drink | B15: Tom Savano Moscow Mule | C15: 0.1 | E15: 12 | H15: Ready To Drink | I15: Tom Savano Moscow Mule | J15: 0.1 | L15: 12 | AB15: Wine | AC15: Monte Carlo Blush Cans | AD15: 0.125 | AE15: 12 | AF15: Ready To Drink | AG15: Tom Savano Moscow Mule | AH15: 0.1 | AJ15: 12 | AM15: Ready To Drink | AN15: Tom Savano Moscow Mule | AO15: 0.1 | AQ15: 12 | BD15: Ready To Drink | BE15: Tom Savano Moscow Mule | BF15: 0.1 | BH15: 12
B16: Tom Savano Hot Honey Margarita | C16: 0.15 | D16: 12 | I16: Tom Savano Hot Honey Margarita | J16: 0.15 | K16: 12 | AG16: Tom Savano Hot Honey Margarita | AH16: 0.15 | AI16: 12 | AN16: Tom Savano Hot Honey Margarita | AO16: 0.15 | AP16: 12 | BE16: Tom Savano Hot Honey Margarita | BF16: 0.15 | BG16: 12
B17: Tom Savano Caipirinha | C17: 0.15 | D17: 12 | I17: Tom Savano Caipirinha | J17: 0.15 | K17: 12 | AG17: Tom Savano Caipirinha | AH17: 0.15 | AI17: 12 | AN17: Tom Savano Caipirinha | AO17: 0.15 | AP17: 12 | BE17: Tom Savano Caipirinha | BF17: 0.15 | BG17: 12
B18: Hooch Lemon | C18: 0.04 | F18: 7 | I18: Hooch Lemon | J18: 0.04 | M18: 7 | AB18: Softs | AE18: 500ml | AG18: Hooch Lemon | AH18: 0.04 | AK18: 7 | AN18: Hooch Lemon | AO18: 0.04 | AR18: 7 | BE18: Hooch Lemon | BF18: 0.04 | BI18: 7
B19: Hooch Raspberry | C19: 0.034 | F19: 7 | I19: Hooch Raspberry | J19: 0.034 | M19: 7 | AC19: Water | AE19: 3 | AG19: Hooch Raspberry | AH19: 0.034 | AK19: 7 | AN19: Hooch Raspberry | AO19: 0.034 | AR19: 7 | BE19: Hooch Raspberry | BF19: 0.034 | BI19: 7
B20: Hooch Tropical | C20: 0.034 | F20: 7 | I20: Hooch Tropical | J20: 0.034 | M20: 7 | AE20: 330ml | AG20: Hooch Tropical | AH20: 0.034 | AK20: 7 | AN20: Hooch Tropical | AO20: 0.034 | AR20: 7 | BE20: Hooch Tropical | BF20: 0.034 | BI20: 7
B21: Hooch Cherry | C21: 0.043 | F21: 7 | I21: Hooch Cherry | J21: 0.043 | M21: 7 | AC21: CAN Coca Cola Zero 330ml | AE21: 3 | AG21: Hooch Cherry | AH21: 0.043 | AK21: 7 | AN21: Hooch Cherry | AO21: 0.043 | AR21: 7 | BE21: Hooch Cherry | BF21: 0.043 | BI21: 7
B22: Hooch Peach | C22: 0.034 | F22: 7 | I22: Hooch Peach | J22: 0.034 | M22: 7 | AC22: CAN Lemonade 330ml Can | AE22: 3 | AG22: Hooch Peach | AH22: 0.034 | AK22: 7 | AN22: Hooch Peach | AO22: 0.034 | AR22: 7 | BE22: Hooch Peach | BF22: 0.034 | BI22: 7
D23: 25ml | E23: 50ml | K23: 25ml | L23: 50ml | AI23: 25ml | AJ23: 50ml | AP23: 25ml | AQ23: 50ml | BG23: 25ml | BH23: 50ml
A24: Mixed Drinks | B24: Vodka Red Bull | D24: 10.5 | E24: 15.5 | H24: Mixed Drinks | I24: Vodka Red Bull | K24: 10.5 | L24: 15.5 | AF24: Mixed Drinks | AG24: Vodka Red Bull | AI24: 10.5 | AJ24: 15.5 | AM24: Mixed Drinks | AN24: Vodka Red Bull | AP24: 10.5 | AQ24: 15.5 | BD24: Mixed Drinks | BE24: Vodka Red Bull | BG24: 10.5 | BH24: 15.5
B25: Tequila Peach Bull | D25: 10.5 | E25: 15.5 | I25: Tequila Peach Bull | K25: 10.5 | L25: 15.5 | AG25: Tequila Peach Bull | AI25: 10.5 | AJ25: 15.5 | AN25: Tequila Peach Bull | AP25: 10.5 | AQ25: 15.5 | BE25: Tequila Peach Bull | BG25: 10.5 | BH25: 15.5
B26: Citrus Lime Bull | D26: 10.5 | E26: 15.5 | I26: Citrus Lime Bull | K26: 10.5 | L26: 15.5 | AG26: Citrus Lime Bull | AI26: 10.5 | AJ26: 15.5 | AN26: Citrus Lime Bull | AP26: 10.5 | AQ26: 15.5 | BE26: Citrus Lime Bull | BG26: 10.5 | BH26: 15.5
D27: 25ml | E27: 3-4-£15 | K27: 25ml | L27: 3-4-£15 | AI27: 25ml | AJ27: 3-4-£15 | AP27: 25ml | AQ27: 3-4-£15 | BG27: 25ml | BH27: 3-4-£15
A28: Shots | B28: Jagermeister | C28: 0.35 | D28: 6 | H28: Shots | I28: Jagermeister | J28: 0.35 | K28: 6 | AF28: Shots | AG28: Jagermeister | AH28: 0.35 | AI28: 6 | AM28: Shots | AN28: Jagermeister | AO28: 0.35 | AP28: 6 | BD28: Shots | BE28: Jagermeister | BF28: 0.35 | BG28: 6
B29: Jagerbomb | C29: 0.35 | D29: 7.5 | I29: Jagerbomb | J29: 0.35 | K29: 7.5 | AG29: Jagerbomb | AH29: 0.35 | AI29: 7.5 | AN29: Jagerbomb | AO29: 0.35 | AP29: 7.5 | BE29: Jagerbomb | BF29: 0.35 | BG29: 7.5
B30: Tequila Creams | D30: 6 | E30: 15 | I30: Tequila Creams | K30: 6 | L30: 15 | AG30: Tequila Creams | AI30: 6 | AJ30: 15 | AN30: Tequila Creams | AP30: 6 | AQ30: 15 | BE30: Tequila Creams | BG30: 6 | BH30: 15
A31: Wine | D31: Bottle | E31: 250ml | F31: 175ml | G31: 125ml | H31: Wine | K31: Bottle | L31: 250ml | M31: 175ml | N31: 125ml | AF31: Wine | AI31: Bottle | AJ31: 250ml | AK31: 175ml | AL31: 125ml | AM31: Wine | AP31: Bottle | AQ31: 250ml | AR31: 175ml | AS31: 125ml | BD31: Wine | BG31: Bottle | BH31: 250ml | BI31: 175ml | BJ31: 125ml
B32: Richelieu Rose | C32: 0.125 | D32: 33 | E32: 11.5 | F32: 8.2 | G32: 6 | I32: Richelieu Rose | J32: 0.125 | K32: 33 | L32: 11.5 | M32: 8.2 | N32: 6 | AG32: Richelieu Rose | AH32: 0.125 | AI32: 33 | AJ32: 11.5 | AK32: 8.2 | AL32: 6 | AN32: Richelieu Rose | AO32: 0.125 | AP32: 33 | AQ32: 11.5 | AR32: 8.2 | AS32: 6 | BE32: Richelieu Rose | BF32: 0.125 | BG32: 33 | BH32: 11.5 | BI32: 8.2 | BJ32: 6
B33: Richelieu White | C33: 0.125 | D33: 33 | E33: 11.5 | F33: 8.2 | G33: 6 | I33: Richelieu White | J33: 0.125 | K33: 33 | L33: 11.5 | M33: 8.2 | N33: 6 | AG33: Richelieu White | AH33: 0.125 | AI33: 33 | AJ33: 11.5 | AK33: 8.2 | AL33: 6 | AN33: Richelieu White | AO33: 0.125 | AP33: 33 | AQ33: 11.5 | AR33: 8.2 | AS33: 6 | BE33: Richelieu White | BF33: 0.125 | BG33: 33 | BH33: 11.5 | BI33: 8.2 | BJ33: 6
B35: Prosecco | C35: 0.11 | D35: 35 | F35: 8.5 | G35: 6.2 | I35: Prosecco | J35: 0.11 | K35: 35 | M35: 8.5 | N35: 6.2 | AG35: Prosecco | AH35: 0.11 | AI35: 35 | AK35: 8.5 | AL35: 6.2 | AN35: Prosecco | AO35: 0.11 | AP35: 35 | AR35: 8.5 | AS35: 6.2 | BE35: Prosecco | BF35: 0.11 | BG35: 35 | BI35: 8.5 | BJ35: 6.2
B36: Carafe Deposit (+refund needed) | D36: 10 | I36: Carafe Deposit (+refund needed) | K36: 10 | AG36: Carafe Deposit (+refund needed) | AI36: 10 | AN36: Carafe Deposit (+refund needed) | AP36: 10 | BE36: Carafe Deposit (+refund needed) | BG36: 10
A38: Softs | D38: Can | E38: Pint | F38: Half | H38: Softs | K38: Can | L38: Pint | M38: Half | AF38: Softs | AI38: Can | AJ38: Pint | AK38: Half | AM38: Softs | AP38: Can | AQ38: Pint | AR38: Half | BD38: Softs | BG38: Can | BH38: Pint | BI38: Half
B39: Water 500ml | D39: 2.5 | I39: Water 500ml | K39: 2.5 | AG39: Water 500ml | AI39: 2.5 | AN39: Water 500ml | AP39: 2.5 | BE39: Water 500ml | BG39: 2.5
B40: CAN Coca Cola Zero 330ml | D40: 3.2 | I40: CAN Coca Cola Zero 330ml | K40: 3.2 | AG40: CAN Coca Cola Zero 330ml | AI40: 3.2 | AN40: CAN Coca Cola Zero 330ml | AP40: 3.2 | BE40: CAN Coca Cola Zero 330ml | BG40: 3.2
B41: CAN Lemonade 330ml Can | D41: 3.2 | I41: CAN Lemonade 330ml Can | K41: 3.2 | AG41: CAN Lemonade 330ml Can | AI41: 3.2 | AN41: CAN Lemonade 330ml Can | AP41: 3.2 | BE41: CAN Lemonade 330ml Can | BG41: 3.2
B42: Schweppes Tonic 1L PET | E42: 4 | F42: 2 | I42: Schweppes Tonic 1L PET | L42: 4 | M42: 2 | AG42: Schweppes Tonic 1L PET | AJ42: 4 | AK42: 2 | AN42: Schweppes Tonic 1L PET | AQ42: 4 | AR42: 2 | BE42: Schweppes Tonic 1L PET | BH42: 4 | BI42: 2
...

Sheet Photoshop
A1: Photoshop export — do not retype prices here; they pull from the Menu tab automatically.
A2: When prices change: edit the Menu tab as normal, then with THIS tab open do File > Save As > CSV UTF-8 and overwrite menu-data.csv, then run update-menus.jsx in Photoshop.
A3: "Key" = the name to give the matching Photoshop text layer. "File" routes the row to a PSD whose filename contains that tag (normal / vip). Same key on the horizontal & vertical board updates both.
A5: File | B5: Key (Photoshop layer name) | C5: Product | D5: Size | E5: Price
A6: normal | B6: normal_spitfire_lager_pint | C6: Spitfire Lager | D6: Pint | E6: =IF(Menu!D3="","",IF(Menu!D3=INT(Menu!D3),"£"&TEXT(Menu!D3,"0"),"£"&TEXT(Menu!D3,"0.00")))
A7: normal | B7: normal_spitfire_lager_half | C7: Spitfire Lager | D7: Half | E7: =IF(Menu!E3="","",IF(Menu!E3=INT(Menu!E3),"£"&TEXT(Menu!E3,"0"),"£"&TEXT(Menu!E3,"0.00")))
A8: normal | B8: normal_orchard_view_pint | C8: Orchard View | D8: Pint | E8: =IF(Menu!D4="","",IF(Menu!D4=INT(Menu!D4),"£"&TEXT(Menu!D4,"0"),"£"&TEXT(Menu!D4,"0.00")))
A9: normal | B9: normal_orchard_view_half | C9: Orchard View | D9: Half | E9: =IF(Menu!E4="","",IF(Menu!E4=INT(Menu!E4),"£"&TEXT(Menu!E4,"0"),"£"&TEXT(Menu!E4,"0.00")))
A10: normal | B10: normal_smirnoff_vodka_25ml | C10: Smirnoff Vodka | D10: 25ml | E10: =IF(Menu!D7="","",IF(Menu!D7=INT(Menu!D7),"£"&TEXT(Menu!D7,"0"),"£"&TEXT(Menu!D7,"0.00")))
A11: normal | B11: normal_smirnoff_vodka_50ml | C11: Smirnoff Vodka | D11: 50ml | E11: =IF(Menu!E7="","",IF(Menu!E7=INT(Menu!E7),"£"&TEXT(Menu!E7,"0"),"£"&TEXT(Menu!E7,"0.00")))
A12: normal | B12: normal_gordan_s_gin_25ml | C12: Gordan's Gin | D12: 25ml | E12: =IF(Menu!D8="","",IF(Menu!D8=INT(Menu!D8),"£"&TEXT(Menu!D8,"0"),"£"&TEXT(Menu!D8,"0.00")))
A13: normal | B13: normal_gordan_s_gin_50ml | C13: Gordan's Gin | D13: 50ml | E13: =IF(Menu!E8="","",IF(Menu!E8=INT(Menu!E8),"£"&TEXT(Menu!E8,"0"),"£"&TEXT(Menu!E8,"0.00")))
A14: normal | B14: normal_gordan_s_pink_gin_25ml | C14: Gordan's Pink Gin | D14: 25ml | E14: =IF(Menu!D9="","",IF(Menu!D9=INT(Menu!D9),"£"&TEXT(Menu!D9,"0"),"£"&TEXT(Menu!D9,"0.00")))
A15: normal | B15: normal_gordan_s_pink_gin_50ml | C15: Gordan's Pink Gin | D15: 50ml | E15: =IF(Menu!E9="","",IF(Menu!E9=INT(Menu!E9),"£"&TEXT(Menu!E9,"0"),"£"&TEXT(Menu!E9,"0.00")))
A16: normal | B16: normal_captain_morgan_s_spiced_25ml | C16: Captain Morgan's Spiced | D16: 25ml | E16: =IF(Menu!D10="","",IF(Menu!D10=INT(Menu!D10),"£"&TEXT(Menu!D10,"0"),"£"&TEXT(Menu!D10,"0.00")))
A17: normal | B17: normal_captain_morgan_s_spiced_50ml | C17: Captain Morgan's Spiced | D17: 50ml | E17: =IF(Menu!E10="","",IF(Menu!E10=INT(Menu!E10),"£"&TEXT(Menu!E10,"0"),"£"&TEXT(Menu!E10,"0.00")))
A18: normal | B18: normal_jack_danial_s_25ml | C18: Jack Danial's | D18: 25ml | E18: =IF(Menu!D11="","",IF(Menu!D11=INT(Menu!D11),"£"&TEXT(Menu!D11,"0"),"£"&TEXT(Menu!D11,"0.00")))
A19: normal | B19: normal_jack_danial_s_50ml | C19: Jack Danial's | D19: 50ml | E19: =IF(Menu!E11="","",IF(Menu!E11=INT(Menu!E11),"£"&TEXT(Menu!E11,"0"),"£"&TEXT(Menu!E11,"0.00")))
A20: normal | B20: normal_tom_savano_moscow_mule_200ml | C20: Tom Savano Moscow Mule | D20: 200ml | E20: =IF(Menu!E15="","",IF(Menu!E15=INT(Menu!E15),"£"&TEXT(Menu!E15,"0"),"£"&TEXT(Menu!E15,"0.00")))
A21: normal | B21: normal_tom_savano_hot_honey_margarita_125ml | C21: Tom Savano Hot Honey Margarita | D21: 125ml | E21: =IF(Menu!D16="","",IF(Menu!D16=INT(Menu!D16),"£"&TEXT(Menu!D16,"0"),"£"&TEXT(Menu!D16,"0.00")))
A22: normal | B22: normal_tom_savano_caipirinha_125ml | C22: Tom Savano Caipirinha | D22: 125ml | E22: =IF(Menu!D17="","",IF(Menu!D17=INT(Menu!D17),"£"&TEXT(Menu!D17,"0"),"£"&TEXT(Menu!D17,"0.00")))
A23: normal | B23: normal_hooch_lemon_440ml | C23: Hooch Lemon | D23: 440ml | E23: =IF(Menu!F18="","",IF(Menu!F18=INT(Menu!F18),"£"&TEXT(Menu!F18,"0"),"£"&TEXT(Menu!F18,"0.00")))
A24: normal | B24: normal_hooch_raspberry_440ml | C24: Hooch Raspberry | D24: 440ml | E24: =IF(Menu!F19="","",IF(Menu!F19=INT(Menu!F19),"£"&TEXT(Menu!F19,"0"),"£"&TEXT(Menu!F19,"0.00")))
A25: normal | B25: normal_hooch_tropical_440ml | C25: Hooch Tropical | D25: 440ml | E25: =IF(Menu!F20="","",IF(Menu!F20=INT(Menu!F20),"£"&TEXT(Menu!F20,"0"),"£"&TEXT(Menu!F20,"0.00")))
A26: normal | B26: normal_hooch_cherry_440ml | C26: Hooch Cherry | D26: 440ml | E26: =IF(Menu!F21="","",IF(Menu!F21=INT(Menu!F21),"£"&TEXT(Menu!F21,"0"),"£"&TEXT(Menu!F21,"0.00")))
A27: normal | B27: normal_hooch_peach_440ml | C27: Hooch Peach | D27: 440ml | E27: =IF(Menu!F22="","",IF(Menu!F22=INT(Menu!F22),"£"&TEXT(Menu!F22,"0"),"£"&TEXT(Menu!F22,"0.00")))
A28: normal | B28: normal_vodka_red_bull_25ml | C28: Vodka Red Bull | D28: 25ml | E28: =IF(Menu!D24="","",IF(Menu!D24=INT(Menu!D24),"£"&TEXT(Menu!D24,"0"),"£"&TEXT(Menu!D24,"0.00")))
A29: normal | B29: normal_vodka_red_bull_50ml | C29: Vodka Red Bull | D29: 50ml | E29: =IF(Menu!E24="","",IF(Menu!E24=INT(Menu!E24),"£"&TEXT(Menu!E24,"0"),"£"&TEXT(Menu!E24,"0.00")))
A30: normal | B30: normal_tequila_peach_bull_25ml | C30: Tequila Peach Bull | D30: 25ml | E30: =IF(Menu!D25="","",IF(Menu!D25=INT(Menu!D25),"£"&TEXT(Menu!D25,"0"),"£"&TEXT(Menu!D25,"0.00")))
A31: normal | B31: normal_tequila_peach_bull_50ml | C31: Tequila Peach Bull | D31: 50ml | E31: =IF(Menu!E25="","",IF(Menu!E25=INT(Menu!E25),"£"&TEXT(Menu!E25,"0"),"£"&TEXT(Menu!E25,"0.00")))
A32: normal | B32: normal_citrus_lime_bull_25ml | C32: Citrus Lime Bull | D32: 25ml | E32: =IF(Menu!D26="","",IF(Menu!D26=INT(Menu!D26),"£"&TEXT(Menu!D26,"0"),"£"&TEXT(Menu!D26,"0.00")))
A33: normal | B33: normal_citrus_lime_bull_50ml | C33: Citrus Lime Bull | D33: 50ml | E33: =IF(Menu!E26="","",IF(Menu!E26=INT(Menu!E26),"£"&TEXT(Menu!E26,"0"),"£"&TEXT(Menu!E26,"0.00")))
A34: normal | B34: normal_jagermeister_25ml | C34: Jagermeister | D34: 25ml | E34: =IF(Menu!D28="","",IF(Menu!D28=INT(Menu!D28),"£"&TEXT(Menu!D28,"0"),"£"&TEXT(Menu!D28,"0.00")))
A35: normal | B35: normal_jagerbomb_25ml | C35: Jagerbomb | D35: 25ml | E35: =IF(Menu!D29="","",IF(Menu!D29=INT(Menu!D29),"£"&TEXT(Menu!D29,"0"),"£"&TEXT(Menu!D29,"0.00")))
A36: normal | B36: normal_tequila_creams_25ml | C36: Tequila Creams | D36: 25ml | E36: =IF(Menu!D30="","",IF(Menu!D30=INT(Menu!D30),"£"&TEXT(Menu!D30,"0"),"£"&TEXT(Menu!D30,"0.00")))
A37: normal | B37: normal_tequila_creams_3_4_15 | C37: Tequila Creams | D37: 3-4-£15 | E37: =IF(Menu!E30="","",IF(Menu!E30=INT(Menu!E30),"£"&TEXT(Menu!E30,"0"),"£"&TEXT(Menu!E30,"0.00")))
A38: normal | B38: normal_richelieu_rose_bottle | C38: Richelieu Rose | D38: Bottle | E38: =IF(Menu!D32="","",IF(Menu!D32=INT(Menu!D32),"£"&TEXT(Menu!D32,"0"),"£"&TEXT(Menu!D32,"0.00")))
A39: normal | B39: normal_richelieu_rose_250ml | C39: Richelieu Rose | D39: 250ml | E39: =IF(Menu!E32="","",IF(Menu!E32=INT(Menu!E32),"£"&TEXT(Menu!E32,"0"),"£"&TEXT(Menu!E32,"0.00")))
A40: normal | B40: normal_richelieu_rose_175ml | C40: Richelieu Rose | D40: 175ml | E40: =IF(Menu!F32="","",IF(Menu!F32=INT(Menu!F32),"£"&TEXT(Menu!F32,"0"),"£"&TEXT(Menu!F32,"0.00")))
A41: normal | B41: normal_richelieu_rose_125ml | C41: Richelieu Rose | D41: 125ml | E41: =IF(Menu!G32="","",IF(Menu!G32=INT(Menu!G32),"£"&TEXT(Menu!G32,"0"),"£"&TEXT(Menu!G32,"0.00")))
...
